Workbook

Sheet Assumptions
B1: CycloPlus SA — Master data model v1.1 (single source of truth)
B2: Blue = inputs. Provenance: A = validated reference data · B = authored, plausible · C = authored for a clean pedagogical result. Model sheet recomputes from here.
B4: Calendar (value stream brief)
B5: Working days / year | C5: 220 | D5: d/yr | E5: A | F5: VSM brief
B6: Available minutes / day | C6: 480 | D6: min/d | E6: A | F6: 1 shift x 8h, VSM brief
B8: CityLine demand & price
B9: Annual demand | C9: 8000 | D9: units/yr | E9: A | F9: VSM & lines
B10: Average selling price | C10: 800 | D10: CHF | E10: A | F10: reference lines
B11: Totally variable cost / unit | C11: 380 | D11: CHF | E11: C | F11: authored, ~48% of ASP
B13: CityLine assembly — 7 stations (VSM brief)
C14: CT (min) | D14: Setup (min/d) | E14: Prov
B15: Frame & painting | C15: 10 | D15: 225 | E15: A
B16: Fork & steering | C16: 8 | D16: 0 | E16: A
B17: Wheels | C17: 11 | D17: 0 | E17: A
B18: Transmission | C18: 16 | D18: 0 | E18: A
B19: Brakes | C19: 12 | D19: 0 | E19: A
B20: Accessories | C20: 9 | D20: 0 | E20: A
B21: Final inspection | C21: 7 | D21: 0 | E21: A
B23: Performance rate (ch.4, OEE)
B24: Transmission performance rate (TP) | C24: 0.9 | D24: - | E24: C | F24: authored, illustrative performance loss
B26: Observed WIP between stations (VSM brief)
B27: Before WS1 (frames) | C27: 20 | E27: A
B28: WS1-WS2 | C28: 5 | E28: A
B29: WS2-WS3 | C29: 8 | E29: A
B30: WS3-WS4 | C30: 25 | E30: A
B31: WS4-WS5 | C31: 2 | E31: A
B32: WS5-WS6 | C32: 3 | E32: A
B33: WS6-WS7 | C33: 4 | E33: A
B35: Paint capability — thickness µm (capability study brief)
B36: Lower spec limit | C36: 80 | D36: µm | E36: A | F36: Customer spec
B37: Upper spec limit | C37: 120 | D37: µm | E37: A | F37: Customer spec
B38: Mean before | C38: 98 | D38: µm | E38: C | F38: tuned to Cpk 0.46
B39: Std dev before | C39: 13 | D39: µm | E39: C | F39: tuned to Cpk 0.46
B40: Mean after | C40: 100 | D40: µm | E40: C | F40: tuned to Cpk 1.21
B41: Std dev after | C41: 5.5 | D41: µm | E41: C | F41: tuned to Cpk 1.21
B42: Rework cost | C42: 30 | D42: CHF/frame | E42: A | F42: Six Sigma brief
B43: Six Sigma project cost | C43: 30000 | D43: CHF | E43: A | F43: Six Sigma brief
B45: Kingman illustrative station (post-improvement, stable)
B46: Mean effective process time | C46: 13 | D46: min | E46: C | F46: illustrative
B47: CV of arrivals | C47: 0.5 | D47: - | E47: C | F47: illustrative
...

Sheet Model
B1: CycloPlus SA — derived figures (all formulas)
B2: Do not edit. Change inputs on the Assumptions sheet; these recompute.
B4: Calendar & demand
B5: Working weeks / year | C5: =Assumptions!$C$5/5 -> 44 | D5: wk/yr
B6: CityLine daily demand | C6: =Assumptions!$C$9/Assumptions!$C$5 -> 36.363636 | D6: units/d
B7: CityLine weekly demand | C7: =Assumptions!$C$9/$C$5 -> 181.81818 | D7: units/wk
B8: Takt time | C8: =Assumptions!$C$6/$C$6 -> 13.2 | D8: min/unit
B10: Assembly stations — effective capacity
B11: Station | C11: Eff. cap/day | D11: vs takt | E11: vs demand
B12: Frame & painting | C12: =(Assumptions!$C$6-Assumptions!$D$15)/Assumptions!$C$15 -> 25.5 | D12: =IF(Assumptions!$C$15>$C$8,"CT>takt","ok") -> ok | E12: =IF($C$12<$C$6,"SHORT","ok") -> SHORT
B13: Fork & steering | C13: =(Assumptions!$C$6-Assumptions!$D$16)/Assumptions!$C$16 -> 60 | D13: =IF(Assumptions!$C$16>$C$8,"CT>takt","ok") -> ok | E13: =IF($C$13<$C$6,"SHORT","ok") -> ok
B14: Wheels | C14: =(Assumptions!$C$6-Assumptions!$D$17)/Assumptions!$C$17 -> 43.636364 | D14: =IF(Assumptions!$C$17>$C$8,"CT>takt","ok") -> ok | E14: =IF($C$14<$C$6,"SHORT","ok") -> ok
B15: Transmission | C15: =(Assumptions!$C$6-Assumptions!$D$18)/Assumptions!$C$18 -> 30 | D15: =IF(Assumptions!$C$18>$C$8,"CT>takt","ok") -> CT>takt | E15: =IF($C$15<$C$6,"SHORT","ok") -> SHORT
B16: Brakes | C16: =(Assumptions!$C$6-Assumptions!$D$19)/Assumptions!$C$19 -> 40 | D16: =IF(Assumptions!$C$19>$C$8,"CT>takt","ok") -> ok | E16: =IF($C$16<$C$6,"SHORT","ok") -> ok
B17: Accessories | C17: =(Assumptions!$C$6-Assumptions!$D$20)/Assumptions!$C$20 -> 53.333333 | D17: =IF(Assumptions!$C$20>$C$8,"CT>takt","ok") -> ok | E17: =IF($C$17<$C$6,"SHORT","ok") -> ok
B18: Final inspection | C18: =(Assumptions!$C$6-Assumptions!$D$21)/Assumptions!$C$21 -> 68.571429 | D18: =IF(Assumptions!$C$21>$C$8,"CT>takt","ok") -> ok | E18: =IF($C$18<$C$6,"SHORT","ok") -> ok
B19: Line capacity (bottleneck) | C19: =MIN($C$12:$C$18) -> 25.5 | D19: units/d
B20: Shortfall vs demand | C20: =$C$6-$C$19 -> 10.863636 | D20: units/d
B21: Shortfall (%) | C21: =$C$20/$C$6 -> 0.29875 | D21: %
B23: Charge, Capacity and OEE (ch.4)
B24: Painting theoretical capacity (no losses) | C24: =Assumptions!$C$6/Assumptions!$C$15 -> 48 | D24: units/d
B25: Painting operational availability, DO | C25: =(Assumptions!$C$6-Assumptions!$D$15)/Assumptions!$C$6 -> 0.53125 | D25: %
B26: Painting demonstrated capacity (theo. x DO) | C26: =$C$24*$C$25 -> 25.5 | D26: units/d
B28: Transmission demonstrated cycle time (CT/TP) | C28: =Assumptions!$C$18/Assumptions!$C$24 -> 17.777778 | D28: min
B29: Transmission demonstrated capacity | C29: =Assumptions!$C$6/$C$28 -> 27 | D29: units/d
B31: Flow (Little's Law)
B32: Total WIP | C32: =SUM(Assumptions!$C$27:$C$33) -> 67 | D32: units
B33: Value-added time | C33: =Assumptions!$C$15+Assumptions!$C$16+Assumptions!$C$17+Assumptions!$C$18+Assumptions!$C$19+Assumptions!$C$20+Assumptions!$C$21 -> 73 | D33: min
B34: Throughput (= bottleneck) | C34: =$C$19 -> 25.5 | D34: units/d
B35: Flow time | C35: =$C$32/$C$34 -> 2.627451 | D35: d
B36: Flow time | C36: =$C$35*Assumptions!$C$6 -> 1261.1765 | D36: min
B37: Flow efficiency | C37: =$C$33/$C$36 -> 0.057882463 | D37: %
B39: Paint capability & Six Sigma economics
B40: Cp before | C40: =(Assumptions!$C$37-Assumptions!$C$36)/(6*Assumptions!$C$39) -> 0.51282051 | D40: -
B41: Cpk before | C41: =MIN(Assumptions!$C$37-Assumptions!$C$38,Assumptions!$C$38-Assumptions!$C$36)/(3*Assumptions!$C$39) -> 0.46153846 | D41: -
B42: Cpk after | C42: =MIN(Assumptions!$C$37-Assumptions!$C$40,Assumptions!$C$40-Assumptions!$C$36)/(3*Assumptions!$C$41) -> 1.2121212 | D42: -
B43: Defect rate before | C43: =NORMDIST(Assumptions!$C$36,Assumptions!$C$38,Assumptions!$C$39,1)+(1-NORMDIST(Assumptions!$C$37,Assumptions!$C$38,Assumptions!$C$39,1)) -> 0.12837871 | D43: %
B44: Defect rate after | C44: =NORMDIST(Assumptions!$C$36,Assumptions!$C$40,Assumptions!$C$41,1)+(1-NORMDIST(Assumptions!$C$37,Assumptions!$C$40,Assumptions!$C$41,1)) -> 0.00027651392 | D44: %
B45: Frames painted / week | C45: =$C$34*5 -> 127.5 | D45: frames/wk
B46: Weekly rework cost before | C46: =$C$45*$C$43*Assumptions!$C$42 -> 491.04858 | D46: CHF/wk
...
